<?xml version="1.0"?>
<robot name="two_whls_rbt">
    <material name="black">
        <color rgba="0 0 0 1"/>
    </material>
    <material name="red">
        <color rgba="1 0 0 1"/>
    </material>
    <material name="blue">
        <color rgba="0 0 1 1"/>
    </material>
    <link name="link_chassis">
        <!-- pose and inertial -->
        <pose>0 0 0.1 0 0 0</pose>
        <visual>
            <origin rpy = "0 0 0" xyz ="0 0 0"/>
            <geometry>
                <box size="0.5 0.3 0.07" />
            </geometry>
            <material name="blue"/>
        </visual>
        <!-- caster front -->
        <visual name ="caster_front_visual">
            <origin rpy = "0 0 0" xyz = "0.2 0 -0.05"/>
            <geometry>
                <sphere radius="0.05"/>
            </geometry>
        </visual>
    </link>
    <link name="link_right_wheel">
        <visual name = "link_right_wheel_visual">
            <geometry>
                <cylinder length="0.04" radius="0.1"/>
            </geometry>
            <origin rpy="0 1.5707 1.5707" xyz = "0 0 0" />
        </visual>
    </link>
    <link name="link_left_wheel">
        <visual name = "link_left_wheel_visual">
            <geometry>
                <cylinder length="0.04" radius="0.1"/>
            </geometry>
            <origin rpy="0 1.5707 1.5707" xyz = "0 0 0" />
        </visual>
    </link>

    <joint name="join_right_wheel" type="continuous">
        <parent link="link_chassis"/>
        <child link="link_right_wheel"/>
        <origin rpy = "0 0 0" xyz ="-0.05 0.15 0"/>
        <axis rpy = "0 0 0" xyz = "0 1 0" />
        <limit effort="10000" velocity= "1000"/>
        <joint_properties damping="1.0" friction="1.0"/>
    </joint>
    <joint name="joint_left_wheel" type="continuous">
        <parent link="link_chassis"/>
        <child link="link_left_wheel"/>
        <origin rpy = "0 0 0" xyz ="-0.05 -0.15 0"/>
        <axis rpy = "0 0 0" xyz = "0 1 0" />
        <limit effort="10000" velocity= "1000"/>
        <joint_properties damping="1.0" friction="1.0"/>
    </joint>

</robot>
